//Error
//? error is inevitable

// const x = 2; //! when used let x=2; then hit is run in try block
// try {
//   x = 5;
//   console.log("Hit");
// } catch (error) {
//   //   console.log("error");
//   console.log(error.message);
// } finally {
//   console.log("Send Email");
// }
// console.log("hi");

// let name = "Utsarga";
// try {
//   name = "Smarika";
//   console.log("Trial");
// } catch (error) {
//   console.log(error.message);
// }

// try {
//    //  let user = null;
//   let user = { name: "Arun" };
//   if (!user) {
//     throw new Error("user does not exist ");
//   }
//   console.log("Hello there user ");
// } catch (error) {
//   console.log(error.message);
// }
